<?xml version="1.0"?>
<robot xmlns:xacro="http://www.ros.org/wiki/xacro" name="robot_simulation">

  <!-- begin macros definition -->
  <xacro:macro name="base_geometry">
    <origin xyz="0.0 0.0 0.1" rpy="0.0 0.0 0.0"/>
      <geometry>
        <box size="0.6 0.4 0.1"/>
      </geometry>
  </xacro:macro>

  <xacro:macro name="wheel_description" params="name">
    <link name="${name}">
    <inertial>
        <mass value="5.0"/>
        <inertia ixx="1.0" ixy="0.0" ixz="0.0" iyy="1.0" iyz="0.0" izz="1.0"/>
    </inertial>
    <visual>
        <origin xyz="0.0 0.0 0.0" rpy="1.57075 0 0"/>
        <geometry>
            <cylinder radius="0.1" length="0.05"/>
        </geometry>
    </visual>
    <collision>
        <origin xyz="0.0 0.0 0.0" rpy="1.57075 0 0"/>
        <geometry>
            <cylinder radius="0.1" length="0.05"/>
        </geometry>
    </collision>
  </link>
  </xacro:macro>

  <xacro:macro name="joint_desc" params="side side2 x y">
    <joint name="${side}_${side2}_joint" type="continuous">
      <origin xyz="${x} ${y} 0.1" rpy="0.0 0.0 0.0"/>
      <parent link="base_link"/>
      <child link="${side}_${side2}_wheel"/>
      <axis xyz="0.0 1 0.0"/>
    </joint>
  </xacro:macro>

  <xacro:macro name="transmission_desc" params="side side2">
    <transmission name="${side}_${side2}_wheel_trans">
      <type>transmission_interface/SimpleTransmission</type>
      <joint name="${side}_${side2}_joint">
        <hardwareInterface>VelocityJointInterface</hardwareInterface>
      </joint>
      <actuator name="${side}_${side2}_motor">
        <mechanicalReduction>1.0</mechanicalReduction>
      </actuator>
    </transmission>
  </xacro:macro>

  <xacro:macro name="gazebo_wheel" params="ref">
    <gazebo reference="${ref}">
      <mu1 value="200.0"/>
      <mu2 value="100.0"/>
      <kp value="10000000.0" />
      <kd value="1.0" />
      <material>Gazebo/Blue</material>
    </gazebo>
  </xacro:macro>
  <!-- end macros definition -->

  <link name="base_link">
    <inertial>
      <mass value="10"/>
      <inertia ixx="1.0" ixy="0.0" ixz="0.0" iyy="1.0" iyz="0.0" izz="1.0"/>
    </inertial>

    <visual name="base_visual">
      <xacro:base_geometry />
    </visual>
    <collision name="base_collision">
      <xacro:base_geometry />
    </collision>
  </link>

  <link name="front_mark">
    <inertial>
      <mass value="1"/>
      <inertia ixx="1.0" ixy="0.0" ixz="0.0" iyy="1.0" iyz="0.0" izz="1.0"/>
    </inertial>
    <visual>
        <origin xyz="0.0 0.0 0.0" rpy="0 0 0"/>
        <geometry>
            <cylinder radius="0.05" length="0.08"/>
        </geometry>
    </visual>
    <collision>
        <origin xyz="0.0 0.0 0.0" rpy="0 0 0"/>
        <geometry>
            <cylinder radius="0.05" length="0.08"/>
        </geometry>
    </collision>
  </link>

  <joint name="front_mark_joint" type="fixed">
    <origin xyz="0.2 0.0 0.15" rpy="0.0 0.0 0.0"/>
    <parent link="base_link"/>
    <child link="front_mark"/>
  </joint>

  <gazebo reference="front_mark">
      <material>Gazebo/Black</material>
    </gazebo>

  <xacro:wheel_description name="right_front_wheel" />
  <xacro:wheel_description name="right_back_wheel" />
  <xacro:wheel_description name="left_front_wheel" />
  <xacro:wheel_description name="left_back_wheel" />

  <xacro:joint_desc side="right" side2="front" x="0.15" y="-0.226" />
  <xacro:joint_desc side="right" side2="back" x="-0.15" y="-0.226" />
  <xacro:joint_desc side="left" side2="front" x="0.15" y="0.226" />
  <xacro:joint_desc side="left" side2="back" x="-0.15" y="0.226" />

  <xacro:transmission_desc side="right" side2="front" />
  <xacro:transmission_desc side="right" side2="back" />
  <xacro:transmission_desc side="left" side2="front" />
  <xacro:transmission_desc side="left" side2="back" />

  <xacro:gazebo_wheel ref="right_front_wheel" />
  <xacro:gazebo_wheel ref="right_back_wheel" />
  <xacro:gazebo_wheel ref="left_front_wheel" />
  <xacro:gazebo_wheel ref="left_back_wheel" />

  <!--IMU : link, joint, sensor  -->
<link name="imu_link">
  <inertial>
    <mass value="0.001"/>
    <origin rpy="0 0 0" xyz="0 0 0"/>
    <inertia ixx="0.0001" ixy="0" ixz="0" iyy="0.000001" iyz="0" izz="0.0001"/>
  </inertial>
  <visual>
    <origin rpy="0 0 0" xyz="0 0 0"/>
    <geometry>
      <box size="0.01 0.01 0.01"/>
    </geometry>
  </visual>
  <collision>
    <origin rpy="0 0 0" xyz="0 0 0"/>
    <geometry>
      <box size="0.01 0.01 0.01"/>
    </geometry>
  </collision>
</link>

<joint name="imu_joint" type="fixed">
  <axis xyz="1 0 0"/>      
  <origin xyz="0 0 0.105"/>
  <parent link="base_link"/>
  <child link="imu_link"/>
</joint>

<gazebo>
    <plugin name="imu_plugin" filename="libgazebo_ros_imu.so">
      <alwaysOn>true</alwaysOn>
      <bodyName>imu_link</bodyName>
      <topicName>imu</topicName>
      <serviceName>imu_service</serviceName>
      <gaussianNoise>0.0</gaussianNoise>
      <updateRate>20.0</updateRate>
    </plugin>
  </gazebo>

  <!-- Gazebo plugin for ROS Control -->
  <gazebo>
    <plugin name="gazebo_ros_control" filename="libgazebo_ros_control.so">
      <robotNamespace>/</robotNamespace>
    </plugin>
  </gazebo>

</robot>
